<robot name="denso_vs068A2-AV6-NNN-AA">

	<link name="base">
	  <visual>
	    <origin rpy="1.5707 0 0" xyz="0 0 0"/>
	    <geometry>
		<mesh filename="file:///home/johnfaski/ros_ws/src/v068_description/meshes/baselink.stl"/>
	    </geometry>
	    <material name="white">
		<color rgba="1 1 1 1"/>
	    </material>
	  </visual>
	</link>
	
	<joint name="joint1" type="revolute">
		<parent link="base"/>
		<child link="link1"/>
		<origin xyz="4.25 -8.65 6.55" rpy="0 0 0" />
		<axis xyz="0 0 1" />		
		<limit lower="-2.967" upper="2.967" velocity="7.8539" effort="30"/>
	</joint>

	<link name="link1">
	 <visual>
	    <origin xyz="-4.5 -4.75 0" rpy="0 0 0" />
	    <geometry>
		<mesh filename="file:///home/johnfaski/ros_ws/src/v068_description/meshes/link1.stl"/>
	    </geometry>
	    <material name="white">
		<color rgba="1 1 1 1"/>
	    </material>
	  </visual>
	</link> 

	<joint name="joint2" type="revolute">
		<parent link="link1"/>
		<child link="link2"/>
		<origin xyz="1.9 -0.75 8.9" rpy="0 0 0" />
		<axis xyz="1 0 0" />
		<limit lower="-1.7453" upper="2.3562" velocity="6.2831" effort="30"/>
	</joint>

	<link name="link2">
	 <visual>
	   <origin xyz="-5.8 -3.6 -3.2" rpy="0 0 0" />
	    <geometry>
		<mesh filename="file:///home/johnfaski/ros_ws/src/v068_description/meshes/link2.stl"/>
	    </geometry>
	    <material name="white">
		<color rgba="1 1 1 1"/>
	    </material>
	  </visual>
	</link> 

	<joint name="joint3" type="revolute">
		<parent link="link2"/>
		<child link="link3"/>
		<origin xyz="-1.75 -0.25 13.6" rpy="0 0 0" />
		<axis xyz="1 0 0" />
		<limit lower="-2.0944" upper="2.6704" velocity="8.9011" effort="30"/>
	</joint>

	<link name="link3"> 
	 <visual>
	    <origin xyz="-2.25 -7.75 -3" rpy="0 0 0" />
	    <geometry>
		<mesh filename="file:///home/johnfaski/ros_ws/src/v068_description/meshes/link3.stl"/>
	    </geometry>
	    <material name="white">
		<color rgba="1 1 1 1"/>
	    </material>
	  </visual>
	</link>

	<joint name="joint4" type="revolute">
		<parent link="link3"/>
		<child link="link4"/>
		<origin xyz="0.23 -8.7 0.7" rpy="0 0 0" />
		<axis xyz="0 1 0" />
		<limit lower="-4.7124" upper="4.7124" velocity="9.4247" effort="16.2"/>
	</joint>
	
	<link name="link4">
	 <visual>
	    <origin xyz="-2.3 -6.4 -2.25" rpy="0 0 0"/>
	    <geometry>
		<mesh filename="file:///home/johnfaski/ros_ws/src/v068_description/meshes/link4.stl"/>
	    </geometry>
	    <material name="white">
		<color rgba="1 1 1 1"/>
	    </material>
	  </visual>
	</link>

	<joint name="joint5" type="revolute">
		<parent link="link4"/>
		<child link="link5"/>
		<origin xyz="-0.05 -4.25 -0.05" rpy="0 0 0" />
		<axis xyz="1 0 0" />
		<limit lower="-2.0944" upper="2.0944" velocity="9.4247" effort="16.2"/>
	</joint>

	<link name="link5">
	 <visual>
	    <origin xyz="-1.5 -3.52 -1.75" rpy="0 0 0" />
	    <geometry>
		<mesh filename="file:///home/johnfaski/ros_ws/src/v068_description/meshes/link5.stl"/>
	    </geometry>
	    <material name="white">
		<color rgba="1 1 1 1"/>
	    </material>
	  </visual>
	</link>


</robot>






